Workbook

Sheet Dashboard
A1: SignalStack | Team Tempo — Workforce Health Dashboard
A2: Weekly workforce metrics. Update the Hours Log and Roster tabs. KPIs auto-calculate.
A4: TEAM SNAPSHOT — CURRENT WEEK
A5: Headcount | B5: Billable Hours | C5: OT Hours | D5: Utilization % | E5: Avg Pay Rate | F5: Est. Labor Cost
A6: =LOOKUP(2,1/(A10:A2000<>""),B10:B2000) -> #N/A | B6: =LOOKUP(2,1/(A10:A2000<>""),C10:C2000) -> #N/A | C6: =LOOKUP(2,1/(A10:A2000<>""),D10:D2000) -> #N/A | D6: =LOOKUP(2,1/(A10:A2000<>""),E10:E2000) -> #N/A | E6: =AVERAGEIF(Roster!D4:D500,"Active",Roster!E4:E500) -> 26.65 | F6: =E6*B6 -> #N/A
A8: WORKFORCE TREND — FULL HISTORY
A9: Week | B9: Headcount | C9: Billable Hrs | D9: OT Hrs | E9: Utilization % | F9: Turnover | G9: Training Hrs | H9: Notes | J9: __week_start
A10: =IF($J10="","",YEAR($J10-WEEKDAY($J10,2)+4)&"-W"&TEXT(_xludf.ISOWEEKNUM($J10),"00")) -> #NAME? | C10: =IF($J10="","",SUMIFS('Hours Log'!$C:$C,'Hours Log'!$A:$A,">="&$J10,'Hours Log'!$A:$A,"<"&$J10+7)+SUMIFS('Hours Log'!$D:$D,'Hours Log'!$A:$A,">="&$J10,'Hours Log'!$A:$A,"<"&$J10+7)) -> 258 | D10: =IF($J10="","",SUMIFS('Hours Log'!$D:$D,'Hours Log'!$A:$A,">="&$J10,'Hours Log'!$A:$A,"<"&$J10+7)) -> 14 | E10: =IF($J10="","",IFERROR(C10/(B10*40),0)) -> 0 | F10: =IF($J10="","",0) -> 0 | G10: =IF($J10="","",SUMIFS('Hours Log'!$E:$E,'Hours Log'!$A:$A,">="&$J10,'Hours Log'!$A:$A,"<"&$J10+7)) -> 2 | J10: =IF(COUNT('Hours Log'!$A$4:$A$5000)=0,"",IF(MIN('Hours Log'!$A$4:$A$5000)+7*(ROW()-10)>MAX('Hours Log'!$A$4:$A$5000),"",MIN('Hours Log'!$A$4:$A$5000)+7*(ROW()-10))) -> 45614
A11: =IF($J11="","",YEAR($J11-WEEKDAY($J11,2)+4)&"-W"&TEXT(_xludf.ISOWEEKNUM($J11),"00")) -> #NAME? | C11: =IF($J11="","",SUMIFS('Hours Log'!$C:$C,'Hours Log'!$A:$A,">="&$J11,'Hours Log'!$A:$A,"<"&$J11+7)+SUMIFS('Hours Log'!$D:$D,'Hours Log'!$A:$A,">="&$J11,'Hours Log'!$A:$A,"<"&$J11+7)) -> 261 | D11: =IF($J11="","",SUMIFS('Hours Log'!$D:$D,'Hours Log'!$A:$A,">="&$J11,'Hours Log'!$A:$A,"<"&$J11+7)) -> 15 | E11: =IF($J11="","",IFERROR(C11/(B11*40),0)) -> 0 | F11: =IF($J11="","",0) -> 0 | G11: =IF($J11="","",SUMIFS('Hours Log'!$E:$E,'Hours Log'!$A:$A,">="&$J11,'Hours Log'!$A:$A,"<"&$J11+7)) -> 3 | J11: =IF(COUNT('Hours Log'!$A$4:$A$5000)=0,"",IF(MIN('Hours Log'!$A$4:$A$5000)+7*(ROW()-10)>MAX('Hours Log'!$A$4:$A$5000),"",MIN('Hours Log'!$A$4:$A$5000)+7*(ROW()-10))) -> 45621
A12: =IF($J12="","",YEAR($J12-WEEKDAY($J12,2)+4)&"-W"&TEXT(_xludf.ISOWEEKNUM($J12),"00")) -> #NAME? | C12: =IF($J12="","",SUMIFS('Hours Log'!$C:$C,'Hours Log'!$A:$A,">="&$J12,'Hours Log'!$A:$A,"<"&$J12+7)+SUMIFS('Hours Log'!$D:$D,'Hours Log'!$A:$A,">="&$J12,'Hours Log'!$A:$A,"<"&$J12+7)) -> 249 | D12: =IF($J12="","",SUMIFS('Hours Log'!$D:$D,'Hours Log'!$A:$A,">="&$J12,'Hours Log'!$A:$A,"<"&$J12+7)) -> 11 | E12: =IF($J12="","",IFERROR(C12/(B12*40),0)) -> 0 | F12: =IF($J12="","",0) -> 0 | G12: =IF($J12="","",SUMIFS('Hours Log'!$E:$E,'Hours Log'!$A:$A,">="&$J12,'Hours Log'!$A:$A,"<"&$J12+7)) -> 6 | H12: Holiday team training | J12: =IF(COUNT('Hours Log'!$A$4:$A$5000)=0,"",IF(MIN('Hours Log'!$A$4:$A$5000)+7*(ROW()-10)>MAX('Hours Log'!$A$4:$A$5000),"",MIN('Hours Log'!$A$4:$A$5000)+7*(ROW()-10))) -> 45628
A13: =IF($J13="","",YEAR($J13-WEEKDAY($J13,2)+4)&"-W"&TEXT(_xludf.ISOWEEKNUM($J13),"00")) -> #NAME? | C13: =IF($J13="","",SUMIFS('Hours Log'!$C:$C,'Hours Log'!$A:$A,">="&$J13,'Hours Log'!$A:$A,"<"&$J13+7)+SUMIFS('Hours Log'!$D:$D,'Hours Log'!$A:$A,">="&$J13,'Hours Log'!$A:$A,"<"&$J13+7)) -> 238 | D13: =IF($J13="","",SUMIFS('Hours Log'!$D:$D,'Hours Log'!$A:$A,">="&$J13,'Hours Log'!$A:$A,"<"&$J13+7)) -> 8 | E13: =IF($J13="","",IFERROR(C13/(B13*40),0)) -> 0 | F13: =IF($J13="","",0) -> 0 | G13: =IF($J13="","",SUMIFS('Hours Log'!$E:$E,'Hours Log'!$A:$A,">="&$J13,'Hours Log'!$A:$A,"<"&$J13+7)) -> 2 | H13: Short week | J13: =IF(COUNT('Hours Log'!$A$4:$A$5000)=0,"",IF(MIN('Hours Log'!$A$4:$A$5000)+7*(ROW()-10)>MAX('Hours Log'!$A$4:$A$5000),"",MIN('Hours Log'!$A$4:$A$5000)+7*(ROW()-10))) -> 45635
A14: =IF($J14="","",YEAR($J14-WEEKDAY($J14,2)+4)&"-W"&TEXT(_xludf.ISOWEEKNUM($J14),"00")) -> #NAME? | C14: =IF($J14="","",SUMIFS('Hours Log'!$C:$C,'Hours Log'!$A:$A,">="&$J14,'Hours Log'!$A:$A,"<"&$J14+7)+SUMIFS('Hours Log'!$D:$D,'Hours Log'!$A:$A,">="&$J14,'Hours Log'!$A:$A,"<"&$J14+7)) -> 198 | D14: =IF($J14="","",SUMIFS('Hours Log'!$D:$D,'Hours Log'!$A:$A,">="&$J14,'Hours Log'!$A:$A,"<"&$J14+7)) -> 4 | E14: =IF($J14="","",IFERROR(C14/(B14*40),0)) -> 0 | F14: =IF($J14="","",0) -> 0 | G14: =IF($J14="","",SUMIFS('Hours Log'!$E:$E,'Hours Log'!$A:$A,">="&$J14,'Hours Log'!$A:$A,"<"&$J14+7)) -> 0 | H14: Christmas week | J14: =IF(COUNT('Hours Log'!$A$4:$A$5000)=0,"",IF(MIN('Hours Log'!$A$4:$A$5000)+7*(ROW()-10)>MAX('Hours Log'!$A$4:$A$5000),"",MIN('Hours Log'!$A$4:$A$5000)+7*(ROW()-10))) -> 45642
A15: =IF($J15="","",YEAR($J15-WEEKDAY($J15,2)+4)&"-W"&TEXT(_xludf.ISOWEEKNUM($J15),"00")) -> #NAME? | C15: =IF($J15="","",SUMIFS('Hours Log'!$C:$C,'Hours Log'!$A:$A,">="&$J15,'Hours Log'!$A:$A,"<"&$J15+7)+SUMIFS('Hours Log'!$D:$D,'Hours Log'!$A:$A,">="&$J15,'Hours Log'!$A:$A,"<"&$J15+7)) -> 172 | D15: =IF($J15="","",SUMIFS('Hours Log'!$D:$D,'Hours Log'!$A:$A,">="&$J15,'Hours Log'!$A:$A,"<"&$J15+7)) -> 2 | E15: =IF($J15="","",IFERROR(C15/(B15*40),0)) -> 0 | F15: =IF($J15="","",0) -> 0 | G15: =IF($J15="","",SUMIFS('Hours Log'!$E:$E,'Hours Log'!$A:$A,">="&$J15,'Hours Log'!$A:$A,"<"&$J15+7)) -> 0 | H15: New Years week | J15: =IF(COUNT('Hours Log'!$A$4:$A$5000)=0,"",IF(MIN('Hours Log'!$A$4:$A$5000)+7*(ROW()-10)>MAX('Hours Log'!$A$4:$A$5000),"",MIN('Hours Log'!$A$4:$A$5000)+7*(ROW()-10))) -> 45649
A16: =IF($J16="","",YEAR($J16-WEEKDAY($J16,2)+4)&"-W"&TEXT(_xludf.ISOWEEKNUM($J16),"00")) -> #NAME? | C16: =IF($J16="","",SUMIFS('Hours Log'!$C:$C,'Hours Log'!$A:$A,">="&$J16,'Hours Log'!$A:$A,"<"&$J16+7)+SUMIFS('Hours Log'!$D:$D,'Hours Log'!$A:$A,">="&$J16,'Hours Log'!$A:$A,"<"&$J16+7)) -> 255 | D16: =IF($J16="","",SUMIFS('Hours Log'!$D:$D,'Hours Log'!$A:$A,">="&$J16,'Hours Log'!$A:$A,"<"&$J16+7)) -> 12 | E16: =IF($J16="","",IFERROR(C16/(B16*40),0)) -> 0 | F16: =IF($J16="","",0) -> 0 | G16: =IF($J16="","",SUMIFS('Hours Log'!$E:$E,'Hours Log'!$A:$A,">="&$J16,'Hours Log'!$A:$A,"<"&$J16+7)) -> 4 | H16: Full staff return | J16: =IF(COUNT('Hours Log'!$A$4:$A$5000)=0,"",IF(MIN('Hours Log'!$A$4:$A$5000)+7*(ROW()-10)>MAX('Hours Log'!$A$4:$A$5000),"",MIN('Hours Log'!$A$4:$A$5000)+7*(ROW()-10))) -> 45656
A17: =IF($J17="","",YEAR($J17-WEEKDAY($J17,2)+4)&"-W"&TEXT(_xludf.ISOWEEKNUM($J17),"00")) -> #NAME? | C17: =IF($J17="","",SUMIFS('Hours Log'!$C:$C,'Hours Log'!$A:$A,">="&$J17,'Hours Log'!$A:$A,"<"&$J17+7)+SUMIFS('Hours Log'!$D:$D,'Hours Log'!$A:$A,">="&$J17,'Hours Log'!$A:$A,"<"&$J17+7)) -> 262 | D17: =IF($J17="","",SUMIFS('Hours Log'!$D:$D,'Hours Log'!$A:$A,">="&$J17,'Hours Log'!$A:$A,"<"&$J17+7)) -> 16 | E17: =IF($J17="","",IFERROR(C17/(B17*40),0)) -> 0 | F17: =IF($J17="","",0) -> 0 | G17: =IF($J17="","",SUMIFS('Hours Log'!$E:$E,'Hours Log'!$A:$A,">="&$J17,'Hours Log'!$A:$A,"<"&$J17+7)) -> 2 | J17: =IF(COUNT('Hours Log'!$A$4:$A$5000)=0,"",IF(MIN('Hours Log'!$A$4:$A$5000)+7*(ROW()-10)>MAX('Hours Log'!$A$4:$A$5000),"",MIN('Hours Log'!$A$4:$A$5000)+7*(ROW()-10))) -> 45663
A18: =IF($J18="","",YEAR($J18-WEEKDAY($J18,2)+4)&"-W"&TEXT(_xludf.ISOWEEKNUM($J18),"00")) -> #NAME? | C18: =IF($J18="","",SUMIFS('Hours Log'!$C:$C,'Hours Log'!$A:$A,">="&$J18,'Hours Log'!$A:$A,"<"&$J18+7)+SUMIFS('Hours Log'!$D:$D,'Hours Log'!$A:$A,">="&$J18,'Hours Log'!$A:$A,"<"&$J18+7)) -> 268 | D18: =IF($J18="","",SUMIFS('Hours Log'!$D:$D,'Hours Log'!$A:$A,">="&$J18,'Hours Log'!$A:$A,"<"&$J18+7)) -> 17 | E18: =IF($J18="","",IFERROR(C18/(B18*40),0)) -> 0 | F18: =IF($J18="","",0) -> 0 | G18: =IF($J18="","",SUMIFS('Hours Log'!$E:$E,'Hours Log'!$A:$A,">="&$J18,'Hours Log'!$A:$A,"<"&$J18+7)) -> 3 | J18: =IF(COUNT('Hours Log'!$A$4:$A$5000)=0,"",IF(MIN('Hours Log'!$A$4:$A$5000)+7*(ROW()-10)>MAX('Hours Log'!$A$4:$A$5000),"",MIN('Hours Log'!$A$4:$A$5000)+7*(ROW()-10))) -> 45670
A19: =IF($J19="","",YEAR($J19-WEEKDAY($J19,2)+4)&"-W"&TEXT(_xludf.ISOWEEKNUM($J19),"00")) -> #NAME? | C19: =IF($J19="","",SUMIFS('Hours Log'!$C:$C,'Hours Log'!$A:$A,">="&$J19,'Hours Log'!$A:$A,"<"&$J19+7)+SUMIFS('Hours Log'!$D:$D,'Hours Log'!$A:$A,">="&$J19,'Hours Log'!$A:$A,"<"&$J19+7)) -> 264 | D19: =IF($J19="","",SUMIFS('Hours Log'!$D:$D,'Hours Log'!$A:$A,">="&$J19,'Hours Log'!$A:$A,"<"&$J19+7)) -> 15 | E19: =IF($J19="","",IFERROR(C19/(B19*40),0)) -> 0 | F19: =IF($J19="","",0) -> 0 | G19: =IF($J19="","",SUMIFS('Hours Log'!$E:$E,'Hours Log'!$A:$A,">="&$J19,'Hours Log'!$A:$A,"<"&$J19+7)) -> 2 | J19: =IF(COUNT('Hours Log'!$A$4:$A$5000)=0,"",IF(MIN('Hours Log'!$A$4:$A$5000)+7*(ROW()-10)>MAX('Hours Log'!$A$4:$A$5000),"",MIN('Hours Log'!$A$4:$A$5000)+7*(ROW()-10))) -> 45677
A20: =IF($J20="","",YEAR($J20-WEEKDAY($J20,2)+4)&"-W"&TEXT(_xludf.ISOWEEKNUM($J20),"00")) -> #NAME? | C20: =IF($J20="","",SUMIFS('Hours Log'!$C:$C,'Hours Log'!$A:$A,">="&$J20,'Hours Log'!$A:$A,"<"&$J20+7)+SUMIFS('Hours Log'!$D:$D,'Hours Log'!$A:$A,">="&$J20,'Hours Log'!$A:$A,"<"&$J20+7)) -> 271 | D20: =IF($J20="","",SUMIFS('Hours Log'!$D:$D,'Hours Log'!$A:$A,">="&$J20,'Hours Log'!$A:$A,"<"&$J20+7)) -> 18 | E20: =IF($J20="","",IFERROR(C20/(B20*40),0)) -> 0 | F20: =IF($J20="","",0) -> 0 | G20: =IF($J20="","",SUMIFS('Hours Log'!$E:$E,'Hours Log'!$A:$A,">="&$J20,'Hours Log'!$A:$A,"<"&$J20+7)) -> 4 | J20: =IF(COUNT('Hours Log'!$A$4:$A$5000)=0,"",IF(MIN('Hours Log'!$A$4:$A$5000)+7*(ROW()-10)>MAX('Hours Log'!$A$4:$A$5000),"",MIN('Hours Log'!$A$4:$A$5000)+7*(ROW()-10))) -> 45684
A21: =IF($J21="","",YEAR($J21-WEEKDAY($J21,2)+4)&"-W"&TEXT(_xludf.ISOWEEKNUM($J21),"00")) -> #NAME? | C21: =IF($J21="","",SUMIFS('Hours Log'!$C:$C,'Hours Log'!$A:$A,">="&$J21,'Hours Log'!$A:$A,"<"&$J21+7)+SUMIFS('Hours Log'!$D:$D,'Hours Log'!$A:$A,">="&$J21,'Hours Log'!$A:$A,"<"&$J21+7)) -> 269 | D21: =IF($J21="","",SUMIFS('Hours Log'!$D:$D,'Hours Log'!$A:$A,">="&$J21,'Hours Log'!$A:$A,"<"&$J21+7)) -> 17 | E21: =IF($J21="","",IFERROR(C21/(B21*40),0)) -> 0 | F21: =IF($J21="","",0) -> 0 | G21: =IF($J21="","",SUMIFS('Hours Log'!$E:$E,'Hours Log'!$A:$A,">="&$J21,'Hours Log'!$A:$A,"<"&$J21+7)) -> 2 | J21: =IF(COUNT('Hours Log'!$A$4:$A$5000)=0,"",IF(MIN('Hours Log'!$A$4:$A$5000)+7*(ROW()-10)>MAX('Hours Log'!$A$4:$A$5000),"",MIN('Hours Log'!$A$4:$A$5000)+7*(ROW()-10))) -> 45691
A22: =IF($J22="","",YEAR($J22-WEEKDAY($J22,2)+4)&"-W"&TEXT(_xludf.ISOWEEKNUM($J22),"00")) -> #NAME? | C22: =IF($J22="","",SUMIFS('Hours Log'!$C:$C,'Hours Log'!$A:$A,">="&$J22,'Hours Log'!$A:$A,"<"&$J22+7)+SUMIFS('Hours Log'!$D:$D,'Hours Log'!$A:$A,">="&$J22,'Hours Log'!$A:$A,"<"&$J22+7)) -> 274 | D22: =IF($J22="","",SUMIFS('Hours Log'!$D:$D,'Hours Log'!$A:$A,">="&$J22,'Hours Log'!$A:$A,"<"&$J22+7)) -> 19 | E22: =IF($J22="","",IFERROR(C22/(B22*40),0)) -> 0 | F22: =IF($J22="","",0) -> 0 | G22: =IF($J22="","",SUMIFS('Hours Log'!$E:$E,'Hours Log'!$A:$A,">="&$J22,'Hours Log'!$A:$A,"<"&$J22+7)) -> 3 | J22: =IF(COUNT('Hours Log'!$A$4:$A$5000)=0,"",IF(MIN('Hours Log'!$A$4:$A$5000)+7*(ROW()-10)>MAX('Hours Log'!$A$4:$A$5000),"",MIN('Hours Log'!$A$4:$A$5000)+7*(ROW()-10))) -> 45698
A23: =IF($J23="","",YEAR($J23-WEEKDAY($J23,2)+4)&"-W"&TEXT(_xludf.ISOWEEKNUM($J23),"00")) -> #NAME? | C23: =IF($J23="","",SUMIFS('Hours Log'!$C:$C,'Hours Log'!$A:$A,">="&$J23,'Hours Log'!$A:$A,"<"&$J23+7)+SUMIFS('Hours Log'!$D:$D,'Hours Log'!$A:$A,">="&$J23,'Hours Log'!$A:$A,"<"&$J23+7)) -> 276 | D23: =IF($J23="","",SUMIFS('Hours Log'!$D:$D,'Hours Log'!$A:$A,">="&$J23,'Hours Log'!$A:$A,"<"&$J23+7)) -> 20 | E23: =IF($J23="","",IFERROR(C23/(B23*40),0)) -> 0 | F23: =IF($J23="","",0) -> 0 | G23: =IF($J23="","",SUMIFS('Hours Log'!$E:$E,'Hours Log'!$A:$A,">="&$J23,'Hours Log'!$A:$A,"<"&$J23+7)) -> 2 | J23: =IF(COUNT('Hours Log'!$A$4:$A$5000)=0,"",IF(MIN('Hours Log'!$A$4:$A$5000)+7*(ROW()-10)>MAX('Hours Log'!$A$4:$A$5000),"",MIN('Hours Log'!$A$4:$A$5000)+7*(ROW()-10))) -> 45705
A24: =IF($J24="","",YEAR($J24-WEEKDAY($J24,2)+4)&"-W"&TEXT(_xludf.ISOWEEKNUM($J24),"00")) -> #NAME? | C24: =IF($J24="","",SUMIFS('Hours Log'!$C:$C,'Hours Log'!$A:$A,">="&$J24,'Hours Log'!$A:$A,"<"&$J24+7)+SUMIFS('Hours Log'!$D:$D,'Hours Log'!$A:$A,">="&$J24,'Hours Log'!$A:$A,"<"&$J24+7)) -> 271 | D24: =IF($J24="","",SUMIFS('Hours Log'!$D:$D,'Hours Log'!$A:$A,">="&$J24,'Hours Log'!$A:$A,"<"&$J24+7)) -> 18 | E24: =IF($J24="","",IFERROR(C24/(B24*40),0)) -> 0 | F24: =IF($J24="","",0) -> 0 | G24: =IF($J24="","",SUMIFS('Hours Log'!$E:$E,'Hours Log'!$A:$A,">="&$J24,'Hours Log'!$A:$A,"<"&$J24+7)) -> 4 | J24: =IF(COUNT('Hours Log'!$A$4:$A$5000)=0,"",IF(MIN('Hours Log'!$A$4:$A$5000)+7*(ROW()-10)>MAX('Hours Log'!$A$4:$A$5000),"",MIN('Hours Log'!$A$4:$A$5000)+7*(ROW()-10))) -> 45712
A25: =IF($J25="","",YEAR($J25-WEEKDAY($J25,2)+4)&"-W"&TEXT(_xludf.ISOWEEKNUM($J25),"00")) -> #NAME? | C25: =IF($J25="","",SUMIFS('Hours Log'!$C:$C,'Hours Log'!$A:$A,">="&$J25,'Hours Log'!$A:$A,"<"&$J25+7)+SUMIFS('Hours Log'!$D:$D,'Hours Log'!$A:$A,">="&$J25,'Hours Log'!$A:$A,"<"&$J25+7)) -> 278 | D25: =IF($J25="","",SUMIFS('Hours Log'!$D:$D,'Hours Log'!$A:$A,">="&$J25,'Hours Log'!$A:$A,"<"&$J25+7)) -> 20 | E25: =IF($J25="","",IFERROR(C25/(B25*40),0)) -> 0 | F25: =IF($J25="","",0) -> 0 | G25: =IF($J25="","",SUMIFS('Hours Log'!$E:$E,'Hours Log'!$A:$A,">="&$J25,'Hours Log'!$A:$A,"<"&$J25+7)) -> 2 | J25: =IF(COUNT('Hours Log'!$A$4:$A$5000)=0,"",IF(MIN('Hours Log'!$A$4:$A$5000)+7*(ROW()-10)>MAX('Hours Log'!$A$4:$A$5000),"",MIN('Hours Log'!$A$4:$A$5000)+7*(ROW()-10))) -> 45719
A26: =IF($J26="","",YEAR($J26-WEEKDAY($J26,2)+4)&"-W"&TEXT(_xludf.ISOWEEKNUM($J26),"00")) -> #NAME? | C26: =IF($J26="","",SUMIFS('Hours Log'!$C:$C,'Hours Log'!$A:$A,">="&$J26,'Hours Log'!$A:$A,"<"&$J26+7)+SUMIFS('Hours Log'!$D:$D,'Hours Log'!$A:$A,">="&$J26,'Hours Log'!$A:$A,"<"&$J26+7)) -> 265 | D26: =IF($J26="","",SUMIFS('Hours Log'!$D:$D,'Hours Log'!$A:$A,">="&$J26,'Hours Log'!$A:$A,"<"&$J26+7)) -> 15 | E26: =IF($J26="","",IFERROR(C26/(B26*40),0)) -> 0 | F26: =IF($J26="","",0) -> 0 | G26: =IF($J26="","",SUMIFS('Hours Log'!$E:$E,'Hours Log'!$A:$A,">="&$J26,'Hours Log'!$A:$A,"<"&$J26+7)) -> 6 | H26: Safety training | J26: =IF(COUNT('Hours Log'!$A$4:$A$5000)=0,"",IF(MIN('Hours Log'!$A$4:$A$5000)+7*(ROW()-10)>MAX('Hours Log'!$A$4:$A$5000),"",MIN('Hours Log'!$A$4:$A$5000)+7*(ROW()-10))) -> 45726
A27: =IF($J27="","",YEAR($J27-WEEKDAY($J27,2)+4)&"-W"&TEXT(_xludf.ISOWEEKNUM($J27),"00")) -> #NAME? | C27: =IF($J27="","",SUMIFS('Hours Log'!$C:$C,'Hours Log'!$A:$A,">="&$J27,'Hours Log'!$A:$A,"<"&$J27+7)+SUMIFS('Hours Log'!$D:$D,'Hours Log'!$A:$A,">="&$J27,'Hours Log'!$A:$A,"<"&$J27+7)) -> 280 | D27: =IF($J27="","",SUMIFS('Hours Log'!$D:$D,'Hours Log'!$A:$A,">="&$J27,'Hours Log'!$A:$A,"<"&$J27+7)) -> 21 | E27: =IF($J27="","",IFERROR(C27/(B27*40),0)) -> 0 | F27: =IF($J27="","",0) -> 0 | G27: =IF($J27="","",SUMIFS('Hours Log'!$E:$E,'Hours Log'!$A:$A,">="&$J27,'Hours Log'!$A:$A,"<"&$J27+7)) -> 2 | J27: =IF(COUNT('Hours Log'!$A$4:$A$5000)=0,"",IF(MIN('Hours Log'!$A$4:$A$5000)+7*(ROW()-10)>MAX('Hours Log'!$A$4:$A$5000),"",MIN('Hours Log'!$A$4:$A$5000)+7*(ROW()-10))) -> 45733
A28: =IF($J28="","",YEAR($J28-WEEKDAY($J28,2)+4)&"-W"&TEXT(_xludf.ISOWEEKNUM($J28),"00")) -> #NAME? | C28: =IF($J28="","",SUMIFS('Hours Log'!$C:$C,'Hours Log'!$A:$A,">="&$J28,'Hours Log'!$A:$A,"<"&$J28+7)+SUMIFS('Hours Log'!$D:$D,'Hours Log'!$A:$A,">="&$J28,'Hours Log'!$A:$A,"<"&$J28+7)) -> 296 | D28: =IF($J28="","",SUMIFS('Hours Log'!$D:$D,'Hours Log'!$A:$A,">="&$J28,'Hours Log'!$A:$A,"<"&$J28+7)) -> 24 | E28: =IF($J28="","",IFERROR(C28/(B28*40),0)) -> 0 | F28: =IF($J28="","",0) -> 0 | G28: =IF($J28="","",SUMIFS('Hours Log'!$E:$E,'Hours Log'!$A:$A,">="&$J28,'Hours Log'!$A:$A,"<"&$J28+7)) -> 3 | H28: New hire week 1 | J28: =IF(COUNT('Hours Log'!$A$4:$A$5000)=0,"",IF(MIN('Hours Log'!$A$4:$A$5000)+7*(ROW()-10)>MAX('Hours Log'!$A$4:$A$5000),"",MIN('Hours Log'!$A$4:$A$5000)+7*(ROW()-10))) -> 45740
A29: =IF($J29="","",YEAR($J29-WEEKDAY($J29,2)+4)&"-W"&TEXT(_xludf.ISOWEEKNUM($J29),"00")) -> #NAME? | C29: =IF($J29="","",SUMIFS('Hours Log'!$C:$C,'Hours Log'!$A:$A,">="&$J29,'Hours Log'!$A:$A,"<"&$J29+7)+SUMIFS('Hours Log'!$D:$D,'Hours Log'!$A:$A,">="&$J29,'Hours Log'!$A:$A,"<"&$J29+7)) -> 303 | D29: =IF($J29="","",SUMIFS('Hours Log'!$D:$D,'Hours Log'!$A:$A,">="&$J29,'Hours Log'!$A:$A,"<"&$J29+7)) -> 26 | E29: =IF($J29="","",IFERROR(C29/(B29*40),0)) -> 0 | F29: =IF($J29="","",0) -> 0 | G29: =IF($J29="","",SUMIFS('Hours Log'!$E:$E,'Hours Log'!$A:$A,">="&$J29,'Hours Log'!$A:$A,"<"&$J29+7)) -> 2 | J29: =IF(COUNT('Hours Log'!$A$4:$A$5000)=0,"",IF(MIN('Hours Log'!$A$4:$A$5000)+7*(ROW()-10)>MAX('Hours Log'!$A$4:$A$5000),"",MIN('Hours Log'!$A$4:$A$5000)+7*(ROW()-10))) -> 45747
A30: =IF($J30="","",YEAR($J30-WEEKDAY($J30,2)+4)&"-W"&TEXT(_xludf.ISOWEEKNUM($J30),"00")) -> #NAME? | C30: =IF($J30="","",SUMIFS('Hours Log'!$C:$C,'Hours Log'!$A:$A,">="&$J30,'Hours Log'!$A:$A,"<"&$J30+7)+SUMIFS('Hours Log'!$D:$D,'Hours Log'!$A:$A,">="&$J30,'Hours Log'!$A:$A,"<"&$J30+7)) -> 286 | D30: =IF($J30="","",SUMIFS('Hours Log'!$D:$D,'Hours Log'!$A:$A,">="&$J30,'Hours Log'!$A:$A,"<"&$J30+7)) -> 24 | E30: =IF($J30="","",IFERROR(C30/(B30*40),0)) -> 0 | F30: =IF($J30="","",0) -> 0 | G30: =IF($J30="","",SUMIFS('Hours Log'!$E:$E,'Hours Log'!$A:$A,">="&$J30,'Hours Log'!$A:$A,"<"&$J30+7)) -> 3 | H30: Backfill in progress | J30: =IF(COUNT('Hours Log'!$A$4:$A$5000)=0,"",IF(MIN('Hours Log'!$A$4:$A$5000)+7*(ROW()-10)>MAX('Hours Log'!$A$4:$A$5000),"",MIN('Hours Log'!$A$4:$A$5000)+7*(ROW()-10))) -> 45754
A31: =IF($J31="","",YEAR($J31-WEEKDAY($J31,2)+4)&"-W"&TEXT(_xludf.ISOWEEKNUM($J31),"00")) -> #NAME? | C31: =IF($J31="","",SUMIFS('Hours Log'!$C:$C,'Hours Log'!$A:$A,">="&$J31,'Hours Log'!$A:$A,"<"&$J31+7)+SUMIFS('Hours Log'!$D:$D,'Hours Log'!$A:$A,">="&$J31,'Hours Log'!$A:$A,"<"&$J31+7)) -> 286 | D31: =IF($J31="","",SUMIFS('Hours Log'!$D:$D,'Hours Log'!$A:$A,">="&$J31,'Hours Log'!$A:$A,"<"&$J31+7)) -> 20 | E31: =IF($J31="","",IFERROR(C31/(B31*40),0)) -> 0 | F31: =IF($J31="","",0) -> 0 | G31: =IF($J31="","",SUMIFS('Hours Log'!$E:$E,'Hours Log'!$A:$A,">="&$J31,'Hours Log'!$A:$A,"<"&$J31+7)) -> 4 | J31: =IF(COUNT('Hours Log'!$A$4:$A$5000)=0,"",IF(MIN('Hours Log'!$A$4:$A$5000)+7*(ROW()-10)>MAX('Hours Log'!$A$4:$A$5000),"",MIN('Hours Log'!$A$4:$A$5000)+7*(ROW()-10))) -> 45761
A32: =IF($J32="","",YEAR($J32-WEEKDAY($J32,2)+4)&"-W"&TEXT(_xludf.ISOWEEKNUM($J32),"00")) -> #NAME? | C32: =IF($J32="","",SUMIFS('Hours Log'!$C:$C,'Hours Log'!$A:$A,">="&$J32,'Hours Log'!$A:$A,"<"&$J32+7)+SUMIFS('Hours Log'!$D:$D,'Hours Log'!$A:$A,">="&$J32,'Hours Log'!$A:$A,"<"&$J32+7)) -> 277 | D32: =IF($J32="","",SUMIFS('Hours Log'!$D:$D,'Hours Log'!$A:$A,">="&$J32,'Hours Log'!$A:$A,"<"&$J32+7)) -> 19 | E32: =IF($J32="","",IFERROR(C32/(B32*40),0)) -> 0 | F32: =IF($J32="","",0) -> 0 | G32: =IF($J32="","",SUMIFS('Hours Log'!$E:$E,'Hours Log'!$A:$A,">="&$J32,'Hours Log'!$A:$A,"<"&$J32+7)) -> 3 | H32: Backfill in progress | J32: =IF(COUNT('Hours Log'!$A$4:$A$5000)=0,"",IF(MIN('Hours Log'!$A$4:$A$5000)+7*(ROW()-10)>MAX('Hours Log'!$A$4:$A$5000),"",MIN('Hours Log'!$A$4:$A$5000)+7*(ROW()-10))) -> 45768
A33: =IF($J33="","",YEAR($J33-WEEKDAY($J33,2)+4)&"-W"&TEXT(_xludf.ISOWEEKNUM($J33),"00")) -> #NAME? | C33: =IF($J33="","",SUMIFS('Hours Log'!$C:$C,'Hours Log'!$A:$A,">="&$J33,'Hours Log'!$A:$A,"<"&$J33+7)+SUMIFS('Hours Log'!$D:$D,'Hours Log'!$A:$A,">="&$J33,'Hours Log'!$A:$A,"<"&$J33+7)) -> 286 | D33: =IF($J33="","",SUMIFS('Hours Log'!$D:$D,'Hours Log'!$A:$A,">="&$J33,'Hours Log'!$A:$A,"<"&$J33+7)) -> 22 | E33: =IF($J33="","",IFERROR(C33/(B33*40),0)) -> 0 | F33: =IF($J33="","",0) -> 0 | G33: =IF($J33="","",SUMIFS('Hours Log'!$E:$E,'Hours Log'!$A:$A,">="&$J33,'Hours Log'!$A:$A,"<"&$J33+7)) -> 2 | J33: =IF(COUNT('Hours Log'!$A$4:$A$5000)=0,"",IF(MIN('Hours Log'!$A$4:$A$5000)+7*(ROW()-10)>MAX('Hours Log'!$A$4:$A$5000),"",MIN('Hours Log'!$A$4:$A$5000)+7*(ROW()-10))) -> 45775
A34: =IF($J34="","",YEAR($J34-WEEKDAY($J34,2)+4)&"-W"&TEXT(_xludf.ISOWEEKNUM($J34),"00")) -> #NAME? | C34: =IF($J34="","",SUMIFS('Hours Log'!$C:$C,'Hours Log'!$A:$A,">="&$J34,'Hours Log'!$A:$A,"<"&$J34+7)+SUMIFS('Hours Log'!$D:$D,'Hours Log'!$A:$A,">="&$J34,'Hours Log'!$A:$A,"<"&$J34+7)) -> 276 | D34: =IF($J34="","",SUMIFS('Hours Log'!$D:$D,'Hours Log'!$A:$A,">="&$J34,'Hours Log'!$A:$A,"<"&$J34+7)) -> 14 | E34: =IF($J34="","",IFERROR(C34/(B34*40),0)) -> 0 | F34: =IF($J34="","",0) -> 0 | G34: =IF($J34="","",SUMIFS('Hours Log'!$E:$E,'Hours Log'!$A:$A,">="&$J34,'Hours Log'!$A:$A,"<"&$J34+7)) -> 8 | J34: =IF(COUNT('Hours Log'!$A$4:$A$5000)=0,"",IF(MIN('Hours Log'!$A$4:$A$5000)+7*(ROW()-10)>MAX('Hours Log'!$A$4:$A$5000),"",MIN('Hours Log'!$A$4:$A$5000)+7*(ROW()-10))) -> 45782
A35: =IF($J35="","",YEAR($J35-WEEKDAY($J35,2)+4)&"-W"&TEXT(_xludf.ISOWEEKNUM($J35),"00")) -> #NAME? | C35: =IF($J35="","",SUMIFS('Hours Log'!$C:$C,'Hours Log'!$A:$A,">="&$J35,'Hours Log'!$A:$A,"<"&$J35+7)+SUMIFS('Hours Log'!$D:$D,'Hours Log'!$A:$A,">="&$J35,'Hours Log'!$A:$A,"<"&$J35+7)) -> 287 | D35: =IF($J35="","",SUMIFS('Hours Log'!$D:$D,'Hours Log'!$A:$A,">="&$J35,'Hours Log'!$A:$A,"<"&$J35+7)) -> 22 | E35: =IF($J35="","",IFERROR(C35/(B35*40),0)) -> 0 | F35: =IF($J35="","",0) -> 0 | G35: =IF($J35="","",SUMIFS('Hours Log'!$E:$E,'Hours Log'!$A:$A,">="&$J35,'Hours Log'!$A:$A,"<"&$J35+7)) -> 4 | J35: =IF(COUNT('Hours Log'!$A$4:$A$5000)=0,"",IF(MIN('Hours Log'!$A$4:$A$5000)+7*(ROW()-10)>MAX('Hours Log'!$A$4:$A$5000),"",MIN('Hours Log'!$A$4:$A$5000)+7*(ROW()-10))) -> 45789
A36: =IF($J36="","",YEAR($J36-WEEKDAY($J36,2)+4)&"-W"&TEXT(_xludf.ISOWEEKNUM($J36),"00")) -> #NAME? | C36: =IF($J36="","",SUMIFS('Hours Log'!$C:$C,'Hours Log'!$A:$A,">="&$J36,'Hours Log'!$A:$A,"<"&$J36+7)+SUMIFS('Hours Log'!$D:$D,'Hours Log'!$A:$A,">="&$J36,'Hours Log'!$A:$A,"<"&$J36+7)) -> 291 | D36: =IF($J36="","",SUMIFS('Hours Log'!$D:$D,'Hours Log'!$A:$A,">="&$J36,'Hours Log'!$A:$A,"<"&$J36+7)) -> 22 | E36: =IF($J36="","",IFERROR(C36/(B36*40),0)) -> 0 | F36: =IF($J36="","",0) -> 0 | G36: =IF($J36="","",SUMIFS('Hours Log'!$E:$E,'Hours Log'!$A:$A,">="&$J36,'Hours Log'!$A:$A,"<"&$J36+7)) -> 3 | J36: =IF(COUNT('Hours Log'!$A$4:$A$5000)=0,"",IF(MIN('Hours Log'!$A$4:$A$5000)+7*(ROW()-10)>MAX('Hours Log'!$A$4:$A$5000),"",MIN('Hours Log'!$A$4:$A$5000)+7*(ROW()-10))) -> 45796
A37: =IF($J37="","",YEAR($J37-WEEKDAY($J37,2)+4)&"-W"&TEXT(_xludf.ISOWEEKNUM($J37),"00")) -> #NAME? | C37: =IF($J37="","",SUMIFS('Hours Log'!$C:$C,'Hours Log'!$A:$A,">="&$J37,'Hours Log'!$A:$A,"<"&$J37+7)+SUMIFS('Hours Log'!$D:$D,'Hours Log'!$A:$A,">="&$J37,'Hours Log'!$A:$A,"<"&$J37+7)) -> 292 | D37: =IF($J37="","",SUMIFS('Hours Log'!$D:$D,'Hours Log'!$A:$A,">="&$J37,'Hours Log'!$A:$A,"<"&$J37+7)) -> 27 | E37: =IF($J37="","",IFERROR(C37/(B37*40),0)) -> 0 | F37: =IF($J37="","",0) -> 0 | G37: =IF($J37="","",SUMIFS('Hours Log'!$E:$E,'Hours Log'!$A:$A,">="&$J37,'Hours Log'!$A:$A,"<"&$J37+7)) -> 1 | J37: =IF(COUNT('Hours Log'!$A$4:$A$5000)=0,"",IF(MIN('Hours Log'!$A$4:$A$5000)+7*(ROW()-10)>MAX('Hours Log'!$A$4:$A$5000),"",MIN('Hours Log'!$A$4:$A$5000)+7*(ROW()-10))) -> 45803
A38: =IF($J38="","",YEAR($J38-WEEKDAY($J38,2)+4)&"-W"&TEXT(_xludf.ISOWEEKNUM($J38),"00")) -> #NAME? | C38: =IF($J38="","",SUMIFS('Hours Log'!$C:$C,'Hours Log'!$A:$A,">="&$J38,'Hours Log'!$A:$A,"<"&$J38+7)+SUMIFS('Hours Log'!$D:$D,'Hours Log'!$A:$A,">="&$J38,'Hours Log'!$A:$A,"<"&$J38+7)) -> 287 | D38: =IF($J38="","",SUMIFS('Hours Log'!$D:$D,'Hours Log'!$A:$A,">="&$J38,'Hours Log'!$A:$A,"<"&$J38+7)) -> 18 | E38: =IF($J38="","",IFERROR(C38/(B38*40),0)) -> 0 | F38: =IF($J38="","",0) -> 0 | G38: =IF($J38="","",SUMIFS('Hours Log'!$E:$E,'Hours Log'!$A:$A,">="&$J38,'Hours Log'!$A:$A,"<"&$J38+7)) -> 3 | H38: Safety training | J38: =IF(COUNT('Hours Log'!$A$4:$A$5000)=0,"",IF(MIN('Hours Log'!$A$4:$A$5000)+7*(ROW()-10)>MAX('Hours Log'!$A$4:$A$5000),"",MIN('Hours Log'!$A$4:$A$5000)+7*(ROW()-10))) -> 45810
A39: =IF($J39="","",YEAR($J39-WEEKDAY($J39,2)+4)&"-W"&TEXT(_xludf.ISOWEEKNUM($J39),"00")) -> #NAME? | C39: =IF($J39="","",SUMIFS('Hours Log'!$C:$C,'Hours Log'!$A:$A,">="&$J39,'Hours Log'!$A:$A,"<"&$J39+7)+SUMIFS('Hours Log'!$D:$D,'Hours Log'!$A:$A,">="&$J39,'Hours Log'!$A:$A,"<"&$J39+7)) -> 282 | D39: =IF($J39="","",SUMIFS('Hours Log'!$D:$D,'Hours Log'!$A:$A,">="&$J39,'Hours Log'!$A:$A,"<"&$J39+7)) -> 21 | E39: =IF($J39="","",IFERROR(C39/(B39*40),0)) -> 0 | F39: =IF($J39="","",0) -> 0 | G39: =IF($J39="","",SUMIFS('Hours Log'!$E:$E,'Hours Log'!$A:$A,">="&$J39,'Hours Log'!$A:$A,"<"&$J39+7)) -> 3 | J39: =IF(COUNT('Hours Log'!$A$4:$A$5000)=0,"",IF(MIN('Hours Log'!$A$4:$A$5000)+7*(ROW()-10)>MAX('Hours Log'!$A$4:$A$5000),"",MIN('Hours Log'!$A$4:$A$5000)+7*(ROW()-10))) -> 45817
A40: =IF($J40="","",YEAR($J40-WEEKDAY($J40,2)+4)&"-W"&TEXT(_xludf.ISOWEEKNUM($J40),"00")) -> #NAME? | C40: =IF($J40="","",SUMIFS('Hours Log'!$C:$C,'Hours Log'!$A:$A,">="&$J40,'Hours Log'!$A:$A,"<"&$J40+7)+SUMIFS('Hours Log'!$D:$D,'Hours Log'!$A:$A,">="&$J40,'Hours Log'!$A:$A,"<"&$J40+7)) -> 272 | D40: =IF($J40="","",SUMIFS('Hours Log'!$D:$D,'Hours Log'!$A:$A,">="&$J40,'Hours Log'!$A:$A,"<"&$J40+7)) -> 22 | E40: =IF($J40="","",IFERROR(C40/(B40*40),0)) -> 0 | F40: =IF($J40="","",0) -> 0 | G40: =IF($J40="","",SUMIFS('Hours Log'!$E:$E,'Hours Log'!$A:$A,">="&$J40,'Hours Log'!$A:$A,"<"&$J40+7)) -> 4 | J40: =IF(COUNT('Hours Log'!$A$4:$A$5000)=0,"",IF(MIN('Hours Log'!$A$4:$A$5000)+7*(ROW()-10)>MAX('Hours Log'!$A$4:$A$5000),"",MIN('Hours Log'!$A$4:$A$5000)+7*(ROW()-10))) -> 45824
A41: =IF($J41="","",YEAR($J41-WEEKDAY($J41,2)+4)&"-W"&TEXT(_xludf.ISOWEEKNUM($J41),"00")) -> #NAME? | C41: =IF($J41="","",SUMIFS('Hours Log'!$C:$C,'Hours Log'!$A:$A,">="&$J41,'Hours Log'!$A:$A,"<"&$J41+7)+SUMIFS('Hours Log'!$D:$D,'Hours Log'!$A:$A,">="&$J41,'Hours Log'!$A:$A,"<"&$J41+7)) -> 277 | D41: =IF($J41="","",SUMIFS('Hours Log'!$D:$D,'Hours Log'!$A:$A,">="&$J41,'Hours Log'!$A:$A,"<"&$J41+7)) -> 19 | E41: =IF($J41="","",IFERROR(C41/(B41*40),0)) -> 0 | F41: =IF($J41="","",0) -> 0 | G41: =IF($J41="","",SUMIFS('Hours Log'!$E:$E,'Hours Log'!$A:$A,">="&$J41,'Hours Log'!$A:$A,"<"&$J41+7)) -> 3 | H41: Backfill in progress | J41: =IF(COUNT('Hours Log'!$A$4:$A$5000)=0,"",IF(MIN('Hours Log'!$A$4:$A$5000)+7*(ROW()-10)>MAX('Hours Log'!$A$4:$A$5000),"",MIN('Hours Log'!$A$4:$A$5000)+7*(ROW()-10))) -> 45831
A42: =IF($J42="","",YEAR($J42-WEEKDAY($J42,2)+4)&"-W"&TEXT(_xludf.ISOWEEKNUM($J42),"00")) -> #NAME? | C42: =IF($J42="","",SUMIFS('Hours Log'!$C:$C,'Hours Log'!$A:$A,">="&$J42,'Hours Log'!$A:$A,"<"&$J42+7)+SUMIFS('Hours Log'!$D:$D,'Hours Log'!$A:$A,">="&$J42,'Hours Log'!$A:$A,"<"&$J42+7)) -> 271 | D42: =IF($J42="","",SUMIFS('Hours Log'!$D:$D,'Hours Log'!$A:$A,">="&$J42,'Hours Log'!$A:$A,"<"&$J42+7)) -> 17 | E42: =IF($J42="","",IFERROR(C42/(B42*40),0)) -> 0 | F42: =IF($J42="","",0) -> 0 | G42: =IF($J42="","",SUMIFS('Hours Log'!$E:$E,'Hours Log'!$A:$A,">="&$J42,'Hours Log'!$A:$A,"<"&$J42+7)) -> 8 | J42: =IF(COUNT('Hours Log'!$A$4:$A$5000)=0,"",IF(MIN('Hours Log'!$A$4:$A$5000)+7*(ROW()-10)>MAX('Hours Log'!$A$4:$A$5000),"",MIN('Hours Log'!$A$4:$A$5000)+7*(ROW()-10))) -> 45838
...

Sheet Roster
A1: SignalStack | Team Tempo — Employee Roster
A2: One row per employee. Update when roles, rates, or status changes.
A3: Employee | B3: Role | C3: Start Date | D3: Status | E3: Pay Rate | F3: Pay Type | G3: Certifications | H3: Training Due | I3: Notes
A4: Mike Rodriguez | B4: Lead Tech | C4: 05/12/2019 | D4: Active | E4: 32 | F4: Hourly | G4: CDL, OSHA-10 | H4: 09/15/2025
A5: Sara Tran | B5: Field Tech | C5: 03/08/2021 | D5: Active | E5: 28.5 | F5: Hourly | G5: OSHA-10 | H5: 06/30/2025
A6: Chris Beckham | B6: Field Tech | C6: 11/22/2022 | D6: Active | E6: 27 | F6: Hourly | H6: 03/31/2025 | I6: Training overdue
A7: James Liu | B7: Senior Tech | C7: 07/14/2020 | D7: Active | E7: 30 | F7: Hourly | G7: CDL, OSHA-30 | H7: 12/01/2025
A8: Dana Morse | B8: Office Admin | C8: 09/01/2021 | D8: Active | E8: 22 | F8: Hourly | H8: 06/30/2025
A9: Kyle Sutton | B9: Field Tech | C9: 01/10/2023 | D9: Active | E9: 26.5 | F9: Hourly | G9: OSHA-10 | H9: 01/10/2026
A10: Priya Nair | B10: Ops Coordinator | C10: 04/18/2022 | D10: Active | E10: 24 | F10: Hourly | H10: 04/18/2026
A11: Tom Wheeler | B11: Field Tech | C11: 08/05/2024 | D11: Active | E11: 25 | F11: Hourly | H11: 08/05/2025 | I11: Still in 90-day probation
A12: Alex Campos | B12: Field Tech | C12: 06/15/2025 | D12: Active | E12: 26 | F12: Hourly | G12: OSHA-10 | H12: 06/15/2026
A13: Jordan Reeves | B13: Field Tech | C13: 01/06/2026 | D13: Active | E13: 25.5 | F13: Hourly | H13: 01/06/2027 | I13: New hire

Sheet Hours Log
A1: SignalStack | Team Tempo — Weekly Hours Log
A2: Log hours each week per employee. OT = hours over 40 in a week.
A3: Week Of | B3: Employee | C3: Regular Hrs | D3: OT Hrs | E3: Training Hrs | F3: PTO Hrs | G3: Total Hrs
A4: 45614 | B4: Mike Rodriguez | C4: 36.8 | D4: 3.4 | E4: 0 | F4: 0 | G4: =C4+D4+E4+F4 -> 40.2
A5: 45614 | B5: Sara Tran | C5: 17 | D5: 0 | E5: 0.4 | F5: 0 | G5: =C5+D5+E5+F5 -> 17.4
A6: 45614 | B6: Chris Beckham | C6: 25 | D6: 0 | E6: 0 | F6: 0 | G6: =C6+D6+E6+F6 -> 25
A7: 45614 | B7: James Liu | C7: 23.4 | D7: 0 | E7: 0.7 | F7: 0 | G7: =C7+D7+E7+F7 -> 24.1
A8: 45614 | B8: Dana Morse | C8: 39.9 | D8: 0 | E8: 0.6 | F8: 0 | G8: =C8+D8+E8+F8 -> 40.5
A9: 45614 | B9: Kyle Sutton | C9: 38 | D9: 4.8 | E9: 0 | F9: 0 | G9: =C9+D9+E9+F9 -> 42.8
A10: 45614 | B10: Priya Nair | C10: 45 | D10: 2.5 | E10: 0.3 | F10: 0 | G10: =C10+D10+E10+F10 -> 47.8
A11: 45614 | B11: Tom Wheeler | C11: 18.9 | D11: 3.3 | E11: 0 | F11: 0 | G11: =C11+D11+E11+F11 -> 22.2
A12: 45621 | B12: Mike Rodriguez | C12: 27.6 | D12: 3.1 | E12: 0.6 | F12: 0 | G12: =C12+D12+E12+F12 -> 31.3
A13: 45621 | B13: Sara Tran | C13: 19.6 | D13: 4.1 | E13: 0 | F13: 0 | G13: =C13+D13+E13+F13 -> 23.7
A14: 45621 | B14: Chris Beckham | C14: 34.6 | D14: 0 | E14: 0 | F14: 0 | G14: =C14+D14+E14+F14 -> 34.6
A15: 45621 | B15: James Liu | C15: 22.6 | D15: 0 | E15: 0.9 | F15: 0 | G15: =C15+D15+E15+F15 -> 23.5
... A686: 46202 | B686: Alex Campos | C686: 38.3 | D686: 4.6 | E686: 0 | F686: 0 | G686: =C686+D686+E686+F686 -> 42.9
