Workbook

Sheet RAW_INPUT
A1: TNDS Sales Data Template — RAW INPUT (QuickBooks Export)
A2: Drop QuickBooks export here. Required: Date, Qty, Sales Price OR Total Sales. Extra columns are ignored by the pipeline.
A3: Date | B3: Customer | C3: Invoice # | D3: Item / Description | E3: Qty | F3: Sales Price | G3: Total Sales | H3: Tax | I3: Notes
A4: REQUIRED — MM/DD/YYYY | B4: Optional — for reference | C4: Optional — for reference | D4: Optional | E4: REQUIRED if no Total Sales | F4: REQUIRED if no Total Sales | G4: Pipeline uses this (or computes Qty×Price) | H4: Optional | I4: Optional
A5: 45600 | B5: Acme Petroleum | C5: INV-1001 | D5: Diesel Delivery | E5: 420 | F5: 3.91 | G5: =IF(OR(E5="",F5=""),"",E5*F5) -> 1642.2 | H5: 47.62
A6: 45601 | B6: Front Range Inc | C6: INV-1002 | D6: Unleaded Delivery | E6: 380 | F6: 3.91 | G6: =IF(OR(E6="",F6=""),"",E6*F6) -> 1485.8 | H6: 0
A7: 45602 | B7: Arkansas Valley Oil | C7: INV-1003 | D7: Diesel Delivery | E7: 510 | F7: 3.88 | G7: =IF(OR(E7="",F7=""),"",E7*F7) -> 1978.8 | H7: 57.39
A8: 45603 | B8: Summit Logistics | C8: INV-1004 | D8: Fleet Fuel Drop | E8: 465 | F8: 3.88 | G8: =IF(OR(E8="",F8=""),"",E8*F8) -> 1804.2 | H8: 52.32
A9: 45604 | B9: Acme Petroleum | C9: INV-1005 | D9: Diesel Delivery | E9: 490 | F9: 3.85 | G9: =IF(OR(E9="",F9=""),"",E9*F9) -> 1886.5 | H9: 0
A10: 45607 | B10: Springs Delivery Co | C10: INV-1006 | D10: Unleaded Delivery | E10: 440 | F10: 3.85 | G10: =IF(OR(E10="",F10=""),"",E10*F10) -> 1694 | H10: 49.13
A11: 45608 | B11: Front Range Inc | C11: INV-1007 | D11: Fleet Fuel Drop | E11: 520 | F11: 3.82 | G11: =IF(OR(E11="",F11=""),"",E11*F11) -> 1986.4 | H11: 57.61
A12: 45609 | B12: Western Slope Transport | C12: INV-1008 | D12: Fleet Fuel Drop | E12: 478 | F12: 3.82 | G12: =IF(OR(E12="",F12=""),"",E12*F12) -> 1825.96 | H12: 0
A13: 45610 | B13: Pikes Peak Energy | C13: INV-1009 | D13: Fleet Fuel Drop | E13: 502 | F13: 3.8 | G13: =IF(OR(E13="",F13=""),"",E13*F13) -> 1907.6 | H13: 55.32
A14: 45611 | B14: Centennial Hauling | C14: INV-1010 | D14: Diesel Delivery | E14: 461 | F14: 3.8 | G14: =IF(OR(E14="",F14=""),"",E14*F14) -> 1751.8 | H14: 50.8
A15: 45614 | B15: Mountain View Fleet | C15: INV-1011 | D15: Line Flush Service | E15: 1 | F15: 1250 | G15: =IF(OR(E15="",F15=""),"",E15*F15) -> 1250 | H15: 0
A16: 45615 | B16: Centennial Hauling | C16: INV-1012 | D16: Unleaded Delivery | E16: 435 | F16: 3.79 | G16: =IF(OR(E16="",F16=""),"",E16*F16) -> 1648.65 | H16: 47.81
... A445: 46224 | B445: Colorado Fuel Corp | C445: INV-1441 | D445: Synthetic Blend Package | E445: 160 | F445: 45.38 | G445: =IF(OR(E445="",F445=""),"",E445*F445) -> 7260.8 | H445: 210.56

Sheet PIPELINE_READY
A1: PIPELINE_READY — Drop this CSV into data/raw/ after exporting
A2: Minimum viable format. config.py reads: DATE_COLUMN='Date', QTY_COLUMN='Qty', PRICE_COLUMN='Sales Price' OR TARGET_COLUMN='Total Sales'
A3: Date | B3: Qty | C3: Sales Price
A4: =IF(RAW_INPUT!A5="","",RAW_INPUT!A5) -> 45600 | B4: =IF(RAW_INPUT!A5="","",RAW_INPUT!E5) -> 420 | C4: =IF(RAW_INPUT!A5="","",RAW_INPUT!F5) -> 3.91
A5: =IF(RAW_INPUT!A6="","",RAW_INPUT!A6) -> 45601 | B5: =IF(RAW_INPUT!A6="","",RAW_INPUT!E6) -> 380 | C5: =IF(RAW_INPUT!A6="","",RAW_INPUT!F6) -> 3.91
A6: =IF(RAW_INPUT!A7="","",RAW_INPUT!A7) -> 45602 | B6: =IF(RAW_INPUT!A7="","",RAW_INPUT!E7) -> 510 | C6: =IF(RAW_INPUT!A7="","",RAW_INPUT!F7) -> 3.88
A7: =IF(RAW_INPUT!A8="","",RAW_INPUT!A8) -> 45603 | B7: =IF(RAW_INPUT!A8="","",RAW_INPUT!E8) -> 465 | C7: =IF(RAW_INPUT!A8="","",RAW_INPUT!F8) -> 3.88
A8: =IF(RAW_INPUT!A9="","",RAW_INPUT!A9) -> 45604 | B8: =IF(RAW_INPUT!A9="","",RAW_INPUT!E9) -> 490 | C8: =IF(RAW_INPUT!A9="","",RAW_INPUT!F9) -> 3.85
A9: =IF(RAW_INPUT!A10="","",RAW_INPUT!A10) -> 45607 | B9: =IF(RAW_INPUT!A10="","",RAW_INPUT!E10) -> 440 | C9: =IF(RAW_INPUT!A10="","",RAW_INPUT!F10) -> 3.85
A10: =IF(RAW_INPUT!A11="","",RAW_INPUT!A11) -> 45608 | B10: =IF(RAW_INPUT!A11="","",RAW_INPUT!E11) -> 520 | C10: =IF(RAW_INPUT!A11="","",RAW_INPUT!F11) -> 3.82
A11: =IF(RAW_INPUT!A12="","",RAW_INPUT!A12) -> 45609 | B11: =IF(RAW_INPUT!A12="","",RAW_INPUT!E12) -> 478 | C11: =IF(RAW_INPUT!A12="","",RAW_INPUT!F12) -> 3.82
A12: =IF(RAW_INPUT!A13="","",RAW_INPUT!A13) -> 45610 | B12: =IF(RAW_INPUT!A13="","",RAW_INPUT!E13) -> 502 | C12: =IF(RAW_INPUT!A13="","",RAW_INPUT!F13) -> 3.8
A13: =IF(RAW_INPUT!A14="","",RAW_INPUT!A14) -> 45611 | B13: =IF(RAW_INPUT!A14="","",RAW_INPUT!E14) -> 461 | C13: =IF(RAW_INPUT!A14="","",RAW_INPUT!F14) -> 3.8
A14: =IF(RAW_INPUT!A15="","",RAW_INPUT!A15) -> 45614 | B14: =IF(RAW_INPUT!A15="","",RAW_INPUT!E15) -> 1 | C14: =IF(RAW_INPUT!A15="","",RAW_INPUT!F15) -> 1250
A15: =IF(RAW_INPUT!A16="","",RAW_INPUT!A16) -> 45615 | B15: =IF(RAW_INPUT!A16="","",RAW_INPUT!E16) -> 435 | C15: =IF(RAW_INPUT!A16="","",RAW_INPUT!F16) -> 3.79
... A2003: =IF(RAW_INPUT!A2004="","",RAW_INPUT!A2004) | B2003: =IF(RAW_INPUT!A2004="","",RAW_INPUT!E2004) | C2003: =IF(RAW_INPUT!A2004="","",RAW_INPUT!F2004)

Sheet QB_COLUMN_MAP
A1: QuickBooks Export Column Mapping Reference
A2: QuickBooks Column Name | B2: Template Column | C2: Required? | D2: Notes
A3: Date | B3: Date | C3: YES | D3: Transaction date. Rename if QB exports as 'Txn Date'
A4: Qty | B4: Qty | C4: If no Total | D4: Units. May be 'Quantity' in some QB reports
A5: Sales Price | B5: Sales Price | C5: If no Total | D5: Unit price. May be 'Rate' in QB
A6: Amount | B6: Total Sales | C6: If no Qty/Price | D6: Pre-computed total. Rename to 'Total Sales'
A7: Customer | B7: Customer | C7: No | D7: Kept for reference, not used by pipeline
A8: Invoice No. | B8: Invoice # | C8: No | D8: Reference only
A9: Item Description | B9: Item / Description | C9: No | D9: Reference only
A10: Tax | B10: Tax | C10: No | D10: Not used by pipeline currently
A11: Memo | B11: Notes | C11: No | D11: Optional context

Sheet Analysis
A1: TNDS SALES DATA — COMPREHENSIVE ANALYSIS
A2: Source: RAW_INPUT sheet | All figures in USD unless noted
A4: KEY METRICS SUMMARY
A6: Total Revenue | B6: =SUM(RAW_INPUT!G5:G445) -> 790660.08 | D6: Avg Sale Size | E6: =B6/B7 -> 1792.88 | G6: Date Range Start | H6: =MIN(RAW_INPUT!A5:A445) -> 45600
A7: Total Transactions | B7: =COUNTA(RAW_INPUT!A5:A445) -> 441 | D7: Avg Fuel Price/Gal | E7: {=SUMPRODUCT((RAW_INPUT!F5:F445<20)*(RAW_INPUT!G5:G445))/SUMPRODUCT((RAW_INPUT!F5:F445<20)*(RAW_INPUT!E5:E445))} -> 3.6986725 | G7: Date Range End | H7: =MAX(RAW_INPUT!A5:A445) -> 46224
A8: Total Fuel Gallons | B8: {=SUMPRODUCT((RAW_INPUT!F5:F445<20)*(RAW_INPUT!E5:E445))} -> 181158 | D8: Service Transactions | E8: {=SUMPRODUCT((RAW_INPUT!E5:E445=1)*(RAW_INPUT!F5:F445>=20)*1)} -> 72 | G8: Unique Customers | H8: {=SUMPRODUCT(1/COUNTIF(RAW_INPUT!B5:B445,RAW_INPUT!B5:B445))} -> 15
A10: MONTHLY REVENUE TREND
A11: Month | B11: Revenue | C11: # Transactions | D11: Fuel Gallons | E11: Avg Price/Gal | F11: Avg Sale Size
A12: =DATE(YEAR(MIN(RAW_INPUT!A5:A445)),MONTH(MIN(RAW_INPUT!A5:A445)),1) -> 45597 | B12: {=SUMPRODUCT((RAW_INPUT!A5:A445>=A12)*(RAW_INPUT!A5:A445<A13)*RAW_INPUT!G5:G445)} -> 30502.09 | C12: {=SUMPRODUCT((RAW_INPUT!A5:A445>=A12)*(RAW_INPUT!A5:A445<A13)*1)} -> 18 | D12: {=SUMPRODUCT((RAW_INPUT!A5:A445>=A12)*(RAW_INPUT!A5:A445<A13)*(RAW_INPUT!F5:F445<20)*RAW_INPUT!E5:E445)} -> 7660 | E12: {=IFERROR(SUMPRODUCT((RAW_INPUT!A5:A445>=A12)*(RAW_INPUT!A5:A445<A13)*(RAW_INPUT!F5:F445<20)*RAW_INPUT!G5:G445)/D12,0)} -> 3.8188107 | F12: =IFERROR(B12/C12,0) -> 1694.5606
A13: =EDATE(A12,1) -> 45627 | B13: {=SUMPRODUCT((RAW_INPUT!A5:A445>=A13)*(RAW_INPUT!A5:A445<A14)*RAW_INPUT!G5:G445)} -> 28816.9 | C13: {=SUMPRODUCT((RAW_INPUT!A5:A445>=A13)*(RAW_INPUT!A5:A445<A14)*1)} -> 21 | D13: {=SUMPRODUCT((RAW_INPUT!A5:A445>=A13)*(RAW_INPUT!A5:A445<A14)*(RAW_INPUT!F5:F445<20)*RAW_INPUT!E5:E445)} -> 6999 | E13: {=IFERROR(SUMPRODUCT((RAW_INPUT!A5:A445>=A13)*(RAW_INPUT!A5:A445<A14)*(RAW_INPUT!F5:F445<20)*RAW_INPUT!G5:G445)/D13,0)} -> 3.6529361 | F13: =IFERROR(B13/C13,0) -> 1372.2333
A14: =EDATE(A12,2) -> 45658 | B14: {=SUMPRODUCT((RAW_INPUT!A5:A445>=A14)*(RAW_INPUT!A5:A445<A15)*RAW_INPUT!G5:G445)} -> 33836.2 | C14: {=SUMPRODUCT((RAW_INPUT!A5:A445>=A14)*(RAW_INPUT!A5:A445<A15)*1)} -> 21 | D14: {=SUMPRODUCT((RAW_INPUT!A5:A445>=A14)*(RAW_INPUT!A5:A445<A15)*(RAW_INPUT!F5:F445<20)*RAW_INPUT!E5:E445)} -> 8338 | E14: {=IFERROR(SUMPRODUCT((RAW_INPUT!A5:A445>=A14)*(RAW_INPUT!A5:A445<A15)*(RAW_INPUT!F5:F445<20)*RAW_INPUT!G5:G445)/D14,0)} -> 3.4524107 | F14: =IFERROR(B14/C14,0) -> 1611.2476
A15: =EDATE(A12,3) -> 45689 | B15: {=SUMPRODUCT((RAW_INPUT!A5:A445>=A15)*(RAW_INPUT!A5:A445<A16)*RAW_INPUT!G5:G445)} -> 37066.84 | C15: {=SUMPRODUCT((RAW_INPUT!A5:A445>=A15)*(RAW_INPUT!A5:A445<A16)*1)} -> 19 | D15: {=SUMPRODUCT((RAW_INPUT!A5:A445>=A15)*(RAW_INPUT!A5:A445<A16)*(RAW_INPUT!F5:F445<20)*RAW_INPUT!E5:E445)} -> 8310 | E15: {=IFERROR(SUMPRODUCT((RAW_INPUT!A5:A445>=A15)*(RAW_INPUT!A5:A445<A16)*(RAW_INPUT!F5:F445<20)*RAW_INPUT!G5:G445)/D15,0)} -> 3.8136992 | F15: =IFERROR(B15/C15,0) -> 1950.8863
A16: =EDATE(A12,4) -> 45717 | B16: {=SUMPRODUCT((RAW_INPUT!A5:A445>=A16)*(RAW_INPUT!A5:A445<A17)*RAW_INPUT!G5:G445)} -> 38946.24 | C16: {=SUMPRODUCT((RAW_INPUT!A5:A445>=A16)*(RAW_INPUT!A5:A445<A17)*1)} -> 21 | D16: {=SUMPRODUCT((RAW_INPUT!A5:A445>=A16)*(RAW_INPUT!A5:A445<A17)*(RAW_INPUT!F5:F445<20)*RAW_INPUT!E5:E445)} -> 9023 | E16: {=IFERROR(SUMPRODUCT((RAW_INPUT!A5:A445>=A16)*(RAW_INPUT!A5:A445<A17)*(RAW_INPUT!F5:F445<20)*RAW_INPUT!G5:G445)/D16,0)} -> 3.8392153 | F16: =IFERROR(B16/C16,0) -> 1854.5829
A17: =EDATE(A12,5) -> 45748 | B17: {=SUMPRODUCT((RAW_INPUT!A5:A445>=A17)*(RAW_INPUT!A5:A445<A18)*RAW_INPUT!G5:G445)} -> 34623.6 | C17: {=SUMPRODUCT((RAW_INPUT!A5:A445>=A17)*(RAW_INPUT!A5:A445<A18)*1)} -> 22 | D17: {=SUMPRODUCT((RAW_INPUT!A5:A445>=A17)*(RAW_INPUT!A5:A445<A18)*(RAW_INPUT!F5:F445<20)*RAW_INPUT!E5:E445)} -> 8091 | E17: {=IFERROR(SUMPRODUCT((RAW_INPUT!A5:A445>=A17)*(RAW_INPUT!A5:A445<A18)*(RAW_INPUT!F5:F445<20)*RAW_INPUT!G5:G445)/D17,0)} -> 3.7183846 | F17: =IFERROR(B17/C17,0) -> 1573.8
A18: =EDATE(A12,6) -> 45778 | B18: {=SUMPRODUCT((RAW_INPUT!A5:A445>=A18)*(RAW_INPUT!A5:A445<A19)*RAW_INPUT!G5:G445)} -> 31493.26 | C18: {=SUMPRODUCT((RAW_INPUT!A5:A445>=A18)*(RAW_INPUT!A5:A445<A19)*1)} -> 22 | D18: {=SUMPRODUCT((RAW_INPUT!A5:A445>=A18)*(RAW_INPUT!A5:A445<A19)*(RAW_INPUT!F5:F445<20)*RAW_INPUT!E5:E445)} -> 8007 | E18: {=IFERROR(SUMPRODUCT((RAW_INPUT!A5:A445>=A18)*(RAW_INPUT!A5:A445<A19)*(RAW_INPUT!F5:F445<20)*RAW_INPUT!G5:G445)/D18,0)} -> 3.4926352 | F18: =IFERROR(B18/C18,0) -> 1431.5118
A19: =EDATE(A12,7) -> 45809 | B19: {=SUMPRODUCT((RAW_INPUT!A5:A445>=A19)*(RAW_INPUT!A5:A445<A20)*RAW_INPUT!G5:G445)} -> 40666.24 | C19: {=SUMPRODUCT((RAW_INPUT!A5:A445>=A19)*(RAW_INPUT!A5:A445<A20)*1)} -> 21 | D19: {=SUMPRODUCT((RAW_INPUT!A5:A445>=A19)*(RAW_INPUT!A5:A445<A20)*(RAW_INPUT!F5:F445<20)*RAW_INPUT!E5:E445)} -> 9566 | E19: {=IFERROR(SUMPRODUCT((RAW_INPUT!A5:A445>=A19)*(RAW_INPUT!A5:A445<A20)*(RAW_INPUT!F5:F445<20)*RAW_INPUT!G5:G445)/D19,0)} -> 3.7048934 | F19: =IFERROR(B19/C19,0) -> 1936.4876
A20: =EDATE(A12,8) -> 45839 | B20: {=SUMPRODUCT((RAW_INPUT!A5:A445>=A20)*(RAW_INPUT!A5:A445<A21)*RAW_INPUT!G5:G445)} -> 51448.45 | C20: {=SUMPRODUCT((RAW_INPUT!A5:A445>=A20)*(RAW_INPUT!A5:A445<A21)*1)} -> 23 | D20: {=SUMPRODUCT((RAW_INPUT!A5:A445>=A20)*(RAW_INPUT!A5:A445<A21)*(RAW_INPUT!F5:F445<20)*RAW_INPUT!E5:E445)} -> 10000 | E20: {=IFERROR(SUMPRODUCT((RAW_INPUT!A5:A445>=A20)*(RAW_INPUT!A5:A445<A21)*(RAW_INPUT!F5:F445<20)*RAW_INPUT!G5:G445)/D20,0)} -> 3.840862 | F20: =IFERROR(B20/C20,0) -> 2236.8891
A21: =EDATE(A12,9) -> 45870 | B21: {=SUMPRODUCT((RAW_INPUT!A5:A445>=A21)*(RAW_INPUT!A5:A445<A22)*RAW_INPUT!G5:G445)} -> 34339.14 | C21: {=SUMPRODUCT((RAW_INPUT!A5:A445>=A21)*(RAW_INPUT!A5:A445<A22)*1)} -> 21 | D21: {=SUMPRODUCT((RAW_INPUT!A5:A445>=A21)*(RAW_INPUT!A5:A445<A22)*(RAW_INPUT!F5:F445<20)*RAW_INPUT!E5:E445)} -> 8294 | E21: {=IFERROR(SUMPRODUCT((RAW_INPUT!A5:A445>=A21)*(RAW_INPUT!A5:A445<A22)*(RAW_INPUT!F5:F445<20)*RAW_INPUT!G5:G445)/D21,0)} -> 3.7354425 | F21: =IFERROR(B21/C21,0) -> 1635.1971
A22: =EDATE(A12,10) -> 45901 | B22: {=SUMPRODUCT((RAW_INPUT!A5:A445>=A22)*(RAW_INPUT!A5:A445<A23)*RAW_INPUT!G5:G445)} -> 30597.68 | C22: {=SUMPRODUCT((RAW_INPUT!A5:A445>=A22)*(RAW_INPUT!A5:A445<A23)*1)} -> 22 | D22: {=SUMPRODUCT((RAW_INPUT!A5:A445>=A22)*(RAW_INPUT!A5:A445<A23)*(RAW_INPUT!F5:F445<20)*RAW_INPUT!E5:E445)} -> 7761 | E22: {=IFERROR(SUMPRODUCT((RAW_INPUT!A5:A445>=A22)*(RAW_INPUT!A5:A445<A23)*(RAW_INPUT!F5:F445<20)*RAW_INPUT!G5:G445)/D22,0)} -> 3.5220848 | F22: =IFERROR(B22/C22,0) -> 1390.8036
A23: =EDATE(A12,11) -> 45931 | B23: {=SUMPRODUCT((RAW_INPUT!A5:A445>=A23)*(RAW_INPUT!A5:A445<A24)*RAW_INPUT!G5:G445)} -> 42499.18 | C23: {=SUMPRODUCT((RAW_INPUT!A5:A445>=A23)*(RAW_INPUT!A5:A445<A24)*1)} -> 23 | D23: {=SUMPRODUCT((RAW_INPUT!A5:A445>=A23)*(RAW_INPUT!A5:A445<A24)*(RAW_INPUT!F5:F445<20)*RAW_INPUT!E5:E445)} -> 9880 | E23: {=IFERROR(SUMPRODUCT((RAW_INPUT!A5:A445>=A23)*(RAW_INPUT!A5:A445<A24)*(RAW_INPUT!F5:F445<20)*RAW_INPUT!G5:G445)/D23,0)} -> 3.6711559 | F23: =IFERROR(B23/C23,0) -> 1847.7904
A24: =EDATE(A12,12) -> 45962 | B24: {=SUMPRODUCT((RAW_INPUT!A5:A445>=A24)*(RAW_INPUT!A5:A445<A25)*RAW_INPUT!G5:G445)} -> 45169.68 | C24: {=SUMPRODUCT((RAW_INPUT!A5:A445>=A24)*(RAW_INPUT!A5:A445<A25)*1)} -> 20 | D24: {=SUMPRODUCT((RAW_INPUT!A5:A445>=A24)*(RAW_INPUT!A5:A445<A25)*(RAW_INPUT!F5:F445<20)*RAW_INPUT!E5:E445)} -> 8506 | E24: {=IFERROR(SUMPRODUCT((RAW_INPUT!A5:A445>=A24)*(RAW_INPUT!A5:A445<A25)*(RAW_INPUT!F5:F445<20)*RAW_INPUT!G5:G445)/D24,0)} -> 3.8284246 | F24: =IFERROR(B24/C24,0) -> 2258.484
A25: =EDATE(A12,13) -> 45992 | B25: {=SUMPRODUCT((RAW_INPUT!A5:A445>=A25)*(RAW_INPUT!A5:A445<A26)*RAW_INPUT!G5:G445)} -> 40036.92 | C25: {=SUMPRODUCT((RAW_INPUT!A5:A445>=A25)*(RAW_INPUT!A5:A445<A26)*1)} -> 23 | D25: {=SUMPRODUCT((RAW_INPUT!A5:A445>=A25)*(RAW_INPUT!A5:A445<A26)*(RAW_INPUT!F5:F445<20)*RAW_INPUT!E5:E445)} -> 10094 | E25: {=IFERROR(SUMPRODUCT((RAW_INPUT!A5:A445>=A25)*(RAW_INPUT!A5:A445<A26)*(RAW_INPUT!F5:F445<20)*RAW_INPUT!G5:G445)/D25,0)} -> 3.7634139 | F25: =IFERROR(B25/C25,0) -> 1740.7357
A26: =EDATE(A12,14) -> 46023 | B26: {=SUMPRODUCT((RAW_INPUT!A5:A445>=A26)*(RAW_INPUT!A5:A445<A27)*RAW_INPUT!G5:G445)} -> 31596 | C26: {=SUMPRODUCT((RAW_INPUT!A5:A445>=A26)*(RAW_INPUT!A5:A445<A27)*1)} -> 22 | D26: {=SUMPRODUCT((RAW_INPUT!A5:A445>=A26)*(RAW_INPUT!A5:A445<A27)*(RAW_INPUT!F5:F445<20)*RAW_INPUT!E5:E445)} -> 7521 | E26: {=IFERROR(SUMPRODUCT((RAW_INPUT!A5:A445>=A26)*(RAW_INPUT!A5:A445<A27)*(RAW_INPUT!F5:F445<20)*RAW_INPUT!G5:G445)/D26,0)} -> 3.5460484 | F26: =IFERROR(B26/C26,0) -> 1436.1818
A27: =EDATE(A12,15) -> 46054 | B27: {=SUMPRODUCT((RAW_INPUT!A5:A445>=A27)*(RAW_INPUT!A5:A445<A28)*RAW_INPUT!G5:G445)} -> 38335.35 | C27: {=SUMPRODUCT((RAW_INPUT!A5:A445>=A27)*(RAW_INPUT!A5:A445<A28)*1)} -> 20 | D27: {=SUMPRODUCT((RAW_INPUT!A5:A445>=A27)*(RAW_INPUT!A5:A445<A28)*(RAW_INPUT!F5:F445<20)*RAW_INPUT!E5:E445)} -> 9147 | E27: {=IFERROR(SUMPRODUCT((RAW_INPUT!A5:A445>=A27)*(RAW_INPUT!A5:A445<A28)*(RAW_INPUT!F5:F445<20)*RAW_INPUT!G5:G445)/D27,0)} -> 3.612227 | F27: =IFERROR(B27/C27,0) -> 1916.7675
A28: =EDATE(A12,16) -> 46082 | B28: {=SUMPRODUCT((RAW_INPUT!A5:A445>=A28)*(RAW_INPUT!A5:A445<A29)*RAW_INPUT!G5:G445)} -> 53895.36 | C28: {=SUMPRODUCT((RAW_INPUT!A5:A445>=A28)*(RAW_INPUT!A5:A445<A29)*1)} -> 22 | D28: {=SUMPRODUCT((RAW_INPUT!A5:A445>=A28)*(RAW_INPUT!A5:A445<A29)*(RAW_INPUT!F5:F445<20)*RAW_INPUT!E5:E445)} -> 10152 | E28: {=IFERROR(SUMPRODUCT((RAW_INPUT!A5:A445>=A28)*(RAW_INPUT!A5:A445<A29)*(RAW_INPUT!F5:F445<20)*RAW_INPUT!G5:G445)/D28,0)} -> 3.8064175 | F28: =IFERROR(B28/C28,0) -> 2449.7891
A29: =EDATE(A12,17) -> 46113 | B29: {=SUMPRODUCT((RAW_INPUT!A5:A445>=A29)*(RAW_INPUT!A5:A445<A30)*RAW_INPUT!G5:G445)} -> 39209.54 | C29: {=SUMPRODUCT((RAW_INPUT!A5:A445>=A29)*(RAW_INPUT!A5:A445<A30)*1)} -> 22 | D29: {=SUMPRODUCT((RAW_INPUT!A5:A445>=A29)*(RAW_INPUT!A5:A445<A30)*(RAW_INPUT!F5:F445<20)*RAW_INPUT!E5:E445)} -> 9733 | E29: {=IFERROR(SUMPRODUCT((RAW_INPUT!A5:A445>=A29)*(RAW_INPUT!A5:A445<A30)*(RAW_INPUT!F5:F445<20)*RAW_INPUT!G5:G445)/D29,0)} -> 3.8078105 | F29: =IFERROR(B29/C29,0) -> 1782.2518
A30: =EDATE(A12,18) -> 46143 | B30: {=SUMPRODUCT((RAW_INPUT!A5:A445>=A30)*(RAW_INPUT!A5:A445<A31)*RAW_INPUT!G5:G445)} -> 29912.14 | C30: {=SUMPRODUCT((RAW_INPUT!A5:A445>=A30)*(RAW_INPUT!A5:A445<A31)*1)} -> 21 | D30: {=SUMPRODUCT((RAW_INPUT!A5:A445>=A30)*(RAW_INPUT!A5:A445<A31)*(RAW_INPUT!F5:F445<20)*RAW_INPUT!E5:E445)} -> 7420 | E30: {=IFERROR(SUMPRODUCT((RAW_INPUT!A5:A445>=A30)*(RAW_INPUT!A5:A445<A31)*(RAW_INPUT!F5:F445<20)*RAW_INPUT!G5:G445)/D30,0)} -> 3.5973221 | F30: =IFERROR(B30/C30,0) -> 1424.3876
A31: =EDATE(A12,19) -> 46174 | B31: {=SUMPRODUCT((RAW_INPUT!A5:A445>=A31)*(RAW_INPUT!A5:A445<A32)*RAW_INPUT!G5:G445)} -> 40410.2 | C31: {=SUMPRODUCT((RAW_INPUT!A5:A445>=A31)*(RAW_INPUT!A5:A445<A32)*1)} -> 22 | D31: {=SUMPRODUCT((RAW_INPUT!A5:A445>=A31)*(RAW_INPUT!A5:A445<A32)*(RAW_INPUT!F5:F445<20)*RAW_INPUT!E5:E445)} -> 9498 | E31: {=IFERROR(SUMPRODUCT((RAW_INPUT!A5:A445>=A31)*(RAW_INPUT!A5:A445<A32)*(RAW_INPUT!F5:F445<20)*RAW_INPUT!G5:G445)/D31,0)} -> 3.5440187 | F31: =IFERROR(B31/C31,0) -> 1836.8273
A32: =EDATE(A12,20) -> 46204 | B32: {=SUMPRODUCT((RAW_INPUT!A5:A445>=A32)*(RAW_INPUT!A5:A445<EDATE(A32,1))*RAW_INPUT!G5:G445)} -> 37259.07 | C32: {=SUMPRODUCT((RAW_INPUT!A5:A445>=A32)*(RAW_INPUT!A5:A445<EDATE(A32,1))*1)} -> 15 | D32: {=SUMPRODUCT((RAW_INPUT!A5:A445>=A32)*(RAW_INPUT!A5:A445<EDATE(A32,1))*(RAW_INPUT!F5:F445<20)*RAW_INPUT!E5:E445)} -> 7158 | E32: {=IFERROR(SUMPRODUCT((RAW_INPUT!A5:A445>=A32)*(RAW_INPUT!A5:A445<EDATE(A32,1))*(RAW_INPUT!F5:F445<20)*RAW_INPUT!G5:G445)/D32,0)} -> 3.8134702 | F32: =IFERROR(B32/C32,0) -> 2483.938
A35: CUSTOMER ANALYSIS
A36: Customer | B36: Revenue | C36: % of Total | D36: # Transactions | E36: Avg Sale
A37: Acme Petroleum | B37: =SUMIF(RAW_INPUT!B5:B445,A37,RAW_INPUT!G5:G445) -> 41501.67 | C37: =B37/B$6 -> 0.052489902 | D37: =COUNTIF(RAW_INPUT!B5:B445,A37) -> 24 | E37: =IFERROR(B37/D37,0) -> 1729.2362
A38: Arkansas Valley Oil | B38: =SUMIF(RAW_INPUT!B5:B445,A38,RAW_INPUT!G5:G445) -> 61909.02 | C38: =B38/B$6 -> 0.078300425 | D38: =COUNTIF(RAW_INPUT!B5:B445,A38) -> 31 | E38: =IFERROR(B38/D38,0) -> 1997.0652
A39: Centennial Hauling | B39: =SUMIF(RAW_INPUT!B5:B445,A39,RAW_INPUT!G5:G445) -> 47913.34 | C39: =B39/B$6 -> 0.060599164 | D39: =COUNTIF(RAW_INPUT!B5:B445,A39) -> 30 | E39: =IFERROR(B39/D39,0) -> 1597.1113
A40: Colorado Fuel Corp | B40: =SUMIF(RAW_INPUT!B5:B445,A40,RAW_INPUT!G5:G445) -> 70383.26 | C40: =B40/B$6 -> 0.089018355 | D40: =COUNTIF(RAW_INPUT!B5:B445,A40) -> 37 | E40: =IFERROR(B40/D40,0) -> 1902.2503
A41: Front Range Inc | B41: =SUMIF(RAW_INPUT!B5:B445,A41,RAW_INPUT!G5:G445) -> 62231.92 | C41: =B41/B$6 -> 0.078708818 | D41: =COUNTIF(RAW_INPUT!B5:B445,A41) -> 34 | E41: =IFERROR(B41/D41,0) -> 1830.3506
A42: High Plains Co | B42: =SUMIF(RAW_INPUT!B5:B445,A42,RAW_INPUT!G5:G445) -> 40276.77 | C42: =B42/B$6 -> 0.05094069 | D42: =COUNTIF(RAW_INPUT!B5:B445,A42) -> 23 | E42: =IFERROR(B42/D42,0) -> 1751.1639
A43: Mesa Verde Logistics | B43: =SUMIF(RAW_INPUT!B5:B445,A43,RAW_INPUT!G5:G445) -> 65938.37 | C43: =B43/B$6 -> 0.08339661 | D43: =COUNTIF(RAW_INPUT!B5:B445,A43) -> 32 | E43: =IFERROR(B43/D43,0) -> 2060.5741
A44: Mountain View Fleet | B44: =SUMIF(RAW_INPUT!B5:B445,A44,RAW_INPUT!G5:G445) -> 44276.29 | C44: =B44/B$6 -> 0.055999147 | D44: =COUNTIF(RAW_INPUT!B5:B445,A44) -> 26 | E44: =IFERROR(B44/D44,0) -> 1702.9342
A45: Pikes Peak Energy | B45: =SUMIF(RAW_INPUT!B5:B445,A45,RAW_INPUT!G5:G445) -> 54238.65 | C45: =B45/B$6 -> 0.068599201 | D45: =COUNTIF(RAW_INPUT!B5:B445,A45) -> 31 | E45: =IFERROR(B45/D45,0) -> 1749.6339
...
